/Users/syedsmacbook/Developer/mawaddah-admin-panel/venv/lib/python3.11/site-packages/django/core/handlers/base.py:61: UserWarning: No directory at: /Users/syedsmacbook/Developer/mawaddah-admin-panel/backend/staticfiles/
  mw_instance = middleware(adapted_handler)
/Users/syedsmacbook/Developer/mawaddah-admin-panel/venv/lib/python3.11/site-packages/django/core/handlers/base.py:61: UserWarning: No directory at: /Users/syedsmacbook/Developer/mawaddah-admin-panel/backend/staticfiles/
  mw_instance = middleware(adapted_handler)
Performing system checks...

System check identified no issues (0 silenced).
July 21, 2025 - 11:39:55
Django version 4.2.7, using settings 'mawaddah_backend.settings'
Starting development server at http://0.0.0.0:8000/
Quit the server with CONTROL-C.

/Users/syedsmacbook/Developer/mawaddah-admin-panel/venv/lib/python3.11/site-packages/django/core/handlers/base.py:61: UserWarning: No directory at: /Users/syedsmacbook/Developer/mawaddah-admin-panel/backend/staticfiles/
  mw_instance = middleware(adapted_handler)
Performing system checks...

System check identified no issues (0 silenced).
July 21, 2025 - 11:56:02
Django version 4.2.7, using settings 'mawaddah_backend.settings'
Starting development server at http://0.0.0.0:8000/
Quit the server with CONTROL-C.

Exception in thread django-main-thread:
Traceback (most recent call last):
  File "/usr/local/Cellar/python@3.11/3.11.13/Frameworks/Python.framework/Versions/3.11/lib/python3.11/threading.py", line 1045, in _bootstrap_inner
    self.run()
  File "/usr/local/Cellar/python@3.11/3.11.13/Frameworks/Python.framework/Versions/3.11/lib/python3.11/threading.py", line 982, in run
    self._target(*self._args, **self._kwargs)
  File "/Users/syedsmacbook/Developer/mawaddah-admin-panel/venv/lib/python3.11/site-packages/django/utils/autoreload.py", line 64, in wrapper
    fn(*args, **kwargs)
  File "/Users/syedsmacbook/Developer/mawaddah-admin-panel/venv/lib/python3.11/site-packages/django/core/management/commands/runserver.py", line 136, in inner_run
    self.check_migrations()
  File "/Users/syedsmacbook/Developer/mawaddah-admin-panel/venv/lib/python3.11/site-packages/django/core/management/base.py", line 574, in check_migrations
    executor = MigrationExecutor(connections[DEFAULT_DB_ALIAS])
               ^^^^^^^^^^^^^^^^^^^^^^^^^^^^^^^^^^^^^^^^^^^^^^^^
  File "/Users/syedsmacbook/Developer/mawaddah-admin-panel/venv/lib/python3.11/site-packages/django/db/migrations/executor.py", line 18, in __init__
    self.loader = MigrationLoader(self.connection)
                  ^^^^^^^^^^^^^^^^^^^^^^^^^^^^^^^^
  File "/Users/syedsmacbook/Developer/mawaddah-admin-panel/venv/lib/python3.11/site-packages/django/db/migrations/loader.py", line 58, in __init__
    self.build_graph()
  File "/Users/syedsmacbook/Developer/mawaddah-admin-panel/venv/lib/python3.11/site-packages/django/db/migrations/loader.py", line 235, in build_graph
    self.applied_migrations = recorder.applied_migrations()
                              ^^^^^^^^^^^^^^^^^^^^^^^^^^^^^
  File "/Users/syedsmacbook/Developer/mawaddah-admin-panel/venv/lib/python3.11/site-packages/django/db/migrations/recorder.py", line 81, in applied_migrations
    if self.has_table():
       ^^^^^^^^^^^^^^^^
  File "/Users/syedsmacbook/Developer/mawaddah-admin-panel/venv/lib/python3.11/site-packages/django/db/migrations/recorder.py", line 57, in has_table
    with self.connection.cursor() as cursor:
         ^^^^^^^^^^^^^^^^^^^^^^^^
  File "/Users/syedsmacbook/Developer/mawaddah-admin-panel/venv/lib/python3.11/site-packages/django/utils/asyncio.py", line 26, in inner
    return func(*args, **kwargs)
           ^^^^^^^^^^^^^^^^^^^^^
  File "/Users/syedsmacbook/Developer/mawaddah-admin-panel/venv/lib/python3.11/site-packages/django/db/backends/base/base.py", line 330, in cursor
    return self._cursor()
           ^^^^^^^^^^^^^^
  File "/Users/syedsmacbook/Developer/mawaddah-admin-panel/venv/lib/python3.11/site-packages/django/db/backends/base/base.py", line 306, in _cursor
    self.ensure_connection()
  File "/Users/syedsmacbook/Developer/mawaddah-admin-panel/venv/lib/python3.11/site-packages/django/utils/asyncio.py", line 26, in inner
    return func(*args, **kwargs)
           ^^^^^^^^^^^^^^^^^^^^^
  File "/Users/syedsmacbook/Developer/mawaddah-admin-panel/venv/lib/python3.11/site-packages/django/db/backends/base/base.py", line 289, in ensure_connection
    self.connect()
  File "/Users/syedsmacbook/Developer/mawaddah-admin-panel/venv/lib/python3.11/site-packages/django/utils/asyncio.py", line 26, in inner
    return func(*args, **kwargs)
           ^^^^^^^^^^^^^^^^^^^^^
  File "/Users/syedsmacbook/Developer/mawaddah-admin-panel/venv/lib/python3.11/site-packages/django/db/backends/base/base.py", line 270, in connect
    self.connection = self.get_new_connection(conn_params)
                      ^^^^^^^^^^^^^^^^^^^^^^^^^^^^^^^^^^^^
  File "/Users/syedsmacbook/Developer/mawaddah-admin-panel/venv/lib/python3.11/site-packages/django/utils/asyncio.py", line 26, in inner
    return func(*args, **kwargs)
           ^^^^^^^^^^^^^^^^^^^^^
  File "/Users/syedsmacbook/Developer/mawaddah-admin-panel/venv/lib/python3.11/site-packages/django/db/backends/sqlite3/base.py", line 180, in get_new_connection
    conn = Database.connect(**conn_params)
           ^^^^^^^^^^^^^^^^^^^^^^^^^^^^^^^
TypeError: 'sslmode' is an invalid keyword argument for Connection()
Performing system checks...

System check identified no issues (0 silenced).
Exception in thread django-main-thread:
Traceback (most recent call last):
  File "/usr/local/Cellar/python@3.11/3.11.13/Frameworks/Python.framework/Versions/3.11/lib/python3.11/threading.py", line 1045, in _bootstrap_inner
    self.run()
  File "/usr/local/Cellar/python@3.11/3.11.13/Frameworks/Python.framework/Versions/3.11/lib/python3.11/threading.py", line 982, in run
    self._target(*self._args, **self._kwargs)
  File "/Users/syedsmacbook/Developer/mawaddah-admin-panel/venv/lib/python3.11/site-packages/django/utils/autoreload.py", line 64, in wrapper
    fn(*args, **kwargs)
  File "/Users/syedsmacbook/Developer/mawaddah-admin-panel/venv/lib/python3.11/site-packages/django/core/management/commands/runserver.py", line 136, in inner_run
    self.check_migrations()
  File "/Users/syedsmacbook/Developer/mawaddah-admin-panel/venv/lib/python3.11/site-packages/django/core/management/base.py", line 574, in check_migrations
    executor = MigrationExecutor(connections[DEFAULT_DB_ALIAS])
               ^^^^^^^^^^^^^^^^^^^^^^^^^^^^^^^^^^^^^^^^^^^^^^^^
  File "/Users/syedsmacbook/Developer/mawaddah-admin-panel/venv/lib/python3.11/site-packages/django/db/migrations/executor.py", line 18, in __init__
    self.loader = MigrationLoader(self.connection)
                  ^^^^^^^^^^^^^^^^^^^^^^^^^^^^^^^^
  File "/Users/syedsmacbook/Developer/mawaddah-admin-panel/venv/lib/python3.11/site-packages/django/db/migrations/loader.py", line 58, in __init__
    self.build_graph()
  File "/Users/syedsmacbook/Developer/mawaddah-admin-panel/venv/lib/python3.11/site-packages/django/db/migrations/loader.py", line 235, in build_graph
    self.applied_migrations = recorder.applied_migrations()
                              ^^^^^^^^^^^^^^^^^^^^^^^^^^^^^
  File "/Users/syedsmacbook/Developer/mawaddah-admin-panel/venv/lib/python3.11/site-packages/django/db/migrations/recorder.py", line 81, in applied_migrations
    if self.has_table():
       ^^^^^^^^^^^^^^^^
  File "/Users/syedsmacbook/Developer/mawaddah-admin-panel/venv/lib/python3.11/site-packages/django/db/migrations/recorder.py", line 57, in has_table
    with self.connection.cursor() as cursor:
         ^^^^^^^^^^^^^^^^^^^^^^^^
  File "/Users/syedsmacbook/Developer/mawaddah-admin-panel/venv/lib/python3.11/site-packages/django/utils/asyncio.py", line 26, in inner
    return func(*args, **kwargs)
           ^^^^^^^^^^^^^^^^^^^^^
  File "/Users/syedsmacbook/Developer/mawaddah-admin-panel/venv/lib/python3.11/site-packages/django/db/backends/base/base.py", line 330, in cursor
    return self._cursor()
           ^^^^^^^^^^^^^^
  File "/Users/syedsmacbook/Developer/mawaddah-admin-panel/venv/lib/python3.11/site-packages/django/db/backends/base/base.py", line 306, in _cursor
    self.ensure_connection()
  File "/Users/syedsmacbook/Developer/mawaddah-admin-panel/venv/lib/python3.11/site-packages/django/utils/asyncio.py", line 26, in inner
    return func(*args, **kwargs)
           ^^^^^^^^^^^^^^^^^^^^^
  File "/Users/syedsmacbook/Developer/mawaddah-admin-panel/venv/lib/python3.11/site-packages/django/db/backends/base/base.py", line 289, in ensure_connection
    self.connect()
  File "/Users/syedsmacbook/Developer/mawaddah-admin-panel/venv/lib/python3.11/site-packages/django/utils/asyncio.py", line 26, in inner
    return func(*args, **kwargs)
           ^^^^^^^^^^^^^^^^^^^^^
  File "/Users/syedsmacbook/Developer/mawaddah-admin-panel/venv/lib/python3.11/site-packages/django/db/backends/base/base.py", line 270, in connect
    self.connection = self.get_new_connection(conn_params)
                      ^^^^^^^^^^^^^^^^^^^^^^^^^^^^^^^^^^^^
  File "/Users/syedsmacbook/Developer/mawaddah-admin-panel/venv/lib/python3.11/site-packages/django/utils/asyncio.py", line 26, in inner
    return func(*args, **kwargs)
           ^^^^^^^^^^^^^^^^^^^^^
  File "/Users/syedsmacbook/Developer/mawaddah-admin-panel/venv/lib/python3.11/site-packages/django/db/backends/sqlite3/base.py", line 180, in get_new_connection
    conn = Database.connect(**conn_params)
           ^^^^^^^^^^^^^^^^^^^^^^^^^^^^^^^
TypeError: 'sslmode' is an invalid keyword argument for Connection()
Performing system checks...

System check identified no issues (0 silenced).
Exception in thread django-main-thread:
Traceback (most recent call last):
  File "/usr/local/Cellar/python@3.11/3.11.13/Frameworks/Python.framework/Versions/3.11/lib/python3.11/threading.py", line 1045, in _bootstrap_inner
    self.run()
  File "/usr/local/Cellar/python@3.11/3.11.13/Frameworks/Python.framework/Versions/3.11/lib/python3.11/threading.py", line 982, in run
    self._target(*self._args, **self._kwargs)
  File "/Users/syedsmacbook/Developer/mawaddah-admin-panel/venv/lib/python3.11/site-packages/django/utils/autoreload.py", line 64, in wrapper
    fn(*args, **kwargs)
  File "/Users/syedsmacbook/Developer/mawaddah-admin-panel/venv/lib/python3.11/site-packages/django/core/management/commands/runserver.py", line 136, in inner_run
    self.check_migrations()
  File "/Users/syedsmacbook/Developer/mawaddah-admin-panel/venv/lib/python3.11/site-packages/django/core/management/base.py", line 574, in check_migrations
    executor = MigrationExecutor(connections[DEFAULT_DB_ALIAS])
               ^^^^^^^^^^^^^^^^^^^^^^^^^^^^^^^^^^^^^^^^^^^^^^^^
  File "/Users/syedsmacbook/Developer/mawaddah-admin-panel/venv/lib/python3.11/site-packages/django/db/migrations/executor.py", line 18, in __init__
    self.loader = MigrationLoader(self.connection)
                  ^^^^^^^^^^^^^^^^^^^^^^^^^^^^^^^^
  File "/Users/syedsmacbook/Developer/mawaddah-admin-panel/venv/lib/python3.11/site-packages/django/db/migrations/loader.py", line 58, in __init__
    self.build_graph()
  File "/Users/syedsmacbook/Developer/mawaddah-admin-panel/venv/lib/python3.11/site-packages/django/db/migrations/loader.py", line 235, in build_graph
    self.applied_migrations = recorder.applied_migrations()
                              ^^^^^^^^^^^^^^^^^^^^^^^^^^^^^
  File "/Users/syedsmacbook/Developer/mawaddah-admin-panel/venv/lib/python3.11/site-packages/django/db/migrations/recorder.py", line 81, in applied_migrations
    if self.has_table():
       ^^^^^^^^^^^^^^^^
  File "/Users/syedsmacbook/Developer/mawaddah-admin-panel/venv/lib/python3.11/site-packages/django/db/migrations/recorder.py", line 57, in has_table
    with self.connection.cursor() as cursor:
         ^^^^^^^^^^^^^^^^^^^^^^^^
  File "/Users/syedsmacbook/Developer/mawaddah-admin-panel/venv/lib/python3.11/site-packages/django/utils/asyncio.py", line 26, in inner
    return func(*args, **kwargs)
           ^^^^^^^^^^^^^^^^^^^^^
  File "/Users/syedsmacbook/Developer/mawaddah-admin-panel/venv/lib/python3.11/site-packages/django/db/backends/base/base.py", line 330, in cursor
    return self._cursor()
           ^^^^^^^^^^^^^^
  File "/Users/syedsmacbook/Developer/mawaddah-admin-panel/venv/lib/python3.11/site-packages/django/db/backends/base/base.py", line 306, in _cursor
    self.ensure_connection()
  File "/Users/syedsmacbook/Developer/mawaddah-admin-panel/venv/lib/python3.11/site-packages/django/utils/asyncio.py", line 26, in inner
    return func(*args, **kwargs)
           ^^^^^^^^^^^^^^^^^^^^^
  File "/Users/syedsmacbook/Developer/mawaddah-admin-panel/venv/lib/python3.11/site-packages/django/db/backends/base/base.py", line 289, in ensure_connection
    self.connect()
  File "/Users/syedsmacbook/Developer/mawaddah-admin-panel/venv/lib/python3.11/site-packages/django/utils/asyncio.py", line 26, in inner
    return func(*args, **kwargs)
           ^^^^^^^^^^^^^^^^^^^^^
  File "/Users/syedsmacbook/Developer/mawaddah-admin-panel/venv/lib/python3.11/site-packages/django/db/backends/base/base.py", line 270, in connect
    self.connection = self.get_new_connection(conn_params)
                      ^^^^^^^^^^^^^^^^^^^^^^^^^^^^^^^^^^^^
  File "/Users/syedsmacbook/Developer/mawaddah-admin-panel/venv/lib/python3.11/site-packages/django/utils/asyncio.py", line 26, in inner
    return func(*args, **kwargs)
           ^^^^^^^^^^^^^^^^^^^^^
  File "/Users/syedsmacbook/Developer/mawaddah-admin-panel/venv/lib/python3.11/site-packages/django/db/backends/sqlite3/base.py", line 180, in get_new_connection
    conn = Database.connect(**conn_params)
           ^^^^^^^^^^^^^^^^^^^^^^^^^^^^^^^
TypeError: 'sslmode' is an invalid keyword argument for Connection()
Performing system checks...

System check identified no issues (0 silenced).
Exception in thread django-main-thread:
Traceback (most recent call last):
  File "/usr/local/Cellar/python@3.11/3.11.13/Frameworks/Python.framework/Versions/3.11/lib/python3.11/threading.py", line 1045, in _bootstrap_inner
    self.run()
  File "/usr/local/Cellar/python@3.11/3.11.13/Frameworks/Python.framework/Versions/3.11/lib/python3.11/threading.py", line 982, in run
    self._target(*self._args, **self._kwargs)
  File "/Users/syedsmacbook/Developer/mawaddah-admin-panel/venv/lib/python3.11/site-packages/django/utils/autoreload.py", line 64, in wrapper
    fn(*args, **kwargs)
  File "/Users/syedsmacbook/Developer/mawaddah-admin-panel/venv/lib/python3.11/site-packages/django/core/management/commands/runserver.py", line 136, in inner_run
    self.check_migrations()
  File "/Users/syedsmacbook/Developer/mawaddah-admin-panel/venv/lib/python3.11/site-packages/django/core/management/base.py", line 574, in check_migrations
    executor = MigrationExecutor(connections[DEFAULT_DB_ALIAS])
               ^^^^^^^^^^^^^^^^^^^^^^^^^^^^^^^^^^^^^^^^^^^^^^^^
  File "/Users/syedsmacbook/Developer/mawaddah-admin-panel/venv/lib/python3.11/site-packages/django/db/migrations/executor.py", line 18, in __init__
    self.loader = MigrationLoader(self.connection)
                  ^^^^^^^^^^^^^^^^^^^^^^^^^^^^^^^^
  File "/Users/syedsmacbook/Developer/mawaddah-admin-panel/venv/lib/python3.11/site-packages/django/db/migrations/loader.py", line 58, in __init__
    self.build_graph()
  File "/Users/syedsmacbook/Developer/mawaddah-admin-panel/venv/lib/python3.11/site-packages/django/db/migrations/loader.py", line 235, in build_graph
    self.applied_migrations = recorder.applied_migrations()
                              ^^^^^^^^^^^^^^^^^^^^^^^^^^^^^
  File "/Users/syedsmacbook/Developer/mawaddah-admin-panel/venv/lib/python3.11/site-packages/django/db/migrations/recorder.py", line 81, in applied_migrations
    if self.has_table():
       ^^^^^^^^^^^^^^^^
  File "/Users/syedsmacbook/Developer/mawaddah-admin-panel/venv/lib/python3.11/site-packages/django/db/migrations/recorder.py", line 57, in has_table
    with self.connection.cursor() as cursor:
         ^^^^^^^^^^^^^^^^^^^^^^^^
  File "/Users/syedsmacbook/Developer/mawaddah-admin-panel/venv/lib/python3.11/site-packages/django/utils/asyncio.py", line 26, in inner
    return func(*args, **kwargs)
           ^^^^^^^^^^^^^^^^^^^^^
  File "/Users/syedsmacbook/Developer/mawaddah-admin-panel/venv/lib/python3.11/site-packages/django/db/backends/base/base.py", line 330, in cursor
    return self._cursor()
           ^^^^^^^^^^^^^^
  File "/Users/syedsmacbook/Developer/mawaddah-admin-panel/venv/lib/python3.11/site-packages/django/db/backends/base/base.py", line 306, in _cursor
    self.ensure_connection()
  File "/Users/syedsmacbook/Developer/mawaddah-admin-panel/venv/lib/python3.11/site-packages/django/utils/asyncio.py", line 26, in inner
    return func(*args, **kwargs)
           ^^^^^^^^^^^^^^^^^^^^^
  File "/Users/syedsmacbook/Developer/mawaddah-admin-panel/venv/lib/python3.11/site-packages/django/db/backends/base/base.py", line 289, in ensure_connection
    self.connect()
  File "/Users/syedsmacbook/Developer/mawaddah-admin-panel/venv/lib/python3.11/site-packages/django/utils/asyncio.py", line 26, in inner
    return func(*args, **kwargs)
           ^^^^^^^^^^^^^^^^^^^^^
  File "/Users/syedsmacbook/Developer/mawaddah-admin-panel/venv/lib/python3.11/site-packages/django/db/backends/base/base.py", line 270, in connect
    self.connection = self.get_new_connection(conn_params)
                      ^^^^^^^^^^^^^^^^^^^^^^^^^^^^^^^^^^^^
  File "/Users/syedsmacbook/Developer/mawaddah-admin-panel/venv/lib/python3.11/site-packages/django/utils/asyncio.py", line 26, in inner
    return func(*args, **kwargs)
           ^^^^^^^^^^^^^^^^^^^^^
  File "/Users/syedsmacbook/Developer/mawaddah-admin-panel/venv/lib/python3.11/site-packages/django/db/backends/sqlite3/base.py", line 180, in get_new_connection
    conn = Database.connect(**conn_params)
           ^^^^^^^^^^^^^^^^^^^^^^^^^^^^^^^
TypeError: 'sslmode' is an invalid keyword argument for Connection()
Performing system checks...

System check identified no issues (0 silenced).
Exception in thread django-main-thread:
Traceback (most recent call last):
  File "/usr/local/Cellar/python@3.11/3.11.13/Frameworks/Python.framework/Versions/3.11/lib/python3.11/threading.py", line 1045, in _bootstrap_inner
    self.run()
  File "/usr/local/Cellar/python@3.11/3.11.13/Frameworks/Python.framework/Versions/3.11/lib/python3.11/threading.py", line 982, in run
    self._target(*self._args, **self._kwargs)
  File "/Users/syedsmacbook/Developer/mawaddah-admin-panel/venv/lib/python3.11/site-packages/django/utils/autoreload.py", line 64, in wrapper
    fn(*args, **kwargs)
  File "/Users/syedsmacbook/Developer/mawaddah-admin-panel/venv/lib/python3.11/site-packages/django/core/management/commands/runserver.py", line 136, in inner_run
    self.check_migrations()
  File "/Users/syedsmacbook/Developer/mawaddah-admin-panel/venv/lib/python3.11/site-packages/django/core/management/base.py", line 574, in check_migrations
    executor = MigrationExecutor(connections[DEFAULT_DB_ALIAS])
               ^^^^^^^^^^^^^^^^^^^^^^^^^^^^^^^^^^^^^^^^^^^^^^^^
  File "/Users/syedsmacbook/Developer/mawaddah-admin-panel/venv/lib/python3.11/site-packages/django/db/migrations/executor.py", line 18, in __init__
    self.loader = MigrationLoader(self.connection)
                  ^^^^^^^^^^^^^^^^^^^^^^^^^^^^^^^^
  File "/Users/syedsmacbook/Developer/mawaddah-admin-panel/venv/lib/python3.11/site-packages/django/db/migrations/loader.py", line 58, in __init__
    self.build_graph()
  File "/Users/syedsmacbook/Developer/mawaddah-admin-panel/venv/lib/python3.11/site-packages/django/db/migrations/loader.py", line 235, in build_graph
    self.applied_migrations = recorder.applied_migrations()
                              ^^^^^^^^^^^^^^^^^^^^^^^^^^^^^
  File "/Users/syedsmacbook/Developer/mawaddah-admin-panel/venv/lib/python3.11/site-packages/django/db/migrations/recorder.py", line 81, in applied_migrations
    if self.has_table():
       ^^^^^^^^^^^^^^^^
  File "/Users/syedsmacbook/Developer/mawaddah-admin-panel/venv/lib/python3.11/site-packages/django/db/migrations/recorder.py", line 57, in has_table
    with self.connection.cursor() as cursor:
         ^^^^^^^^^^^^^^^^^^^^^^^^
  File "/Users/syedsmacbook/Developer/mawaddah-admin-panel/venv/lib/python3.11/site-packages/django/utils/asyncio.py", line 26, in inner
    return func(*args, **kwargs)
           ^^^^^^^^^^^^^^^^^^^^^
  File "/Users/syedsmacbook/Developer/mawaddah-admin-panel/venv/lib/python3.11/site-packages/django/db/backends/base/base.py", line 330, in cursor
    return self._cursor()
           ^^^^^^^^^^^^^^
  File "/Users/syedsmacbook/Developer/mawaddah-admin-panel/venv/lib/python3.11/site-packages/django/db/backends/base/base.py", line 306, in _cursor
    self.ensure_connection()
  File "/Users/syedsmacbook/Developer/mawaddah-admin-panel/venv/lib/python3.11/site-packages/django/utils/asyncio.py", line 26, in inner
    return func(*args, **kwargs)
           ^^^^^^^^^^^^^^^^^^^^^
  File "/Users/syedsmacbook/Developer/mawaddah-admin-panel/venv/lib/python3.11/site-packages/django/db/backends/base/base.py", line 289, in ensure_connection
    self.connect()
  File "/Users/syedsmacbook/Developer/mawaddah-admin-panel/venv/lib/python3.11/site-packages/django/utils/asyncio.py", line 26, in inner
    return func(*args, **kwargs)
           ^^^^^^^^^^^^^^^^^^^^^
  File "/Users/syedsmacbook/Developer/mawaddah-admin-panel/venv/lib/python3.11/site-packages/django/db/backends/base/base.py", line 270, in connect
    self.connection = self.get_new_connection(conn_params)
                      ^^^^^^^^^^^^^^^^^^^^^^^^^^^^^^^^^^^^
  File "/Users/syedsmacbook/Developer/mawaddah-admin-panel/venv/lib/python3.11/site-packages/django/utils/asyncio.py", line 26, in inner
    return func(*args, **kwargs)
           ^^^^^^^^^^^^^^^^^^^^^
  File "/Users/syedsmacbook/Developer/mawaddah-admin-panel/venv/lib/python3.11/site-packages/django/db/backends/sqlite3/base.py", line 180, in get_new_connection
    conn = Database.connect(**conn_params)
           ^^^^^^^^^^^^^^^^^^^^^^^^^^^^^^^
TypeError: 'sslmode' is an invalid keyword argument for Connection()
Performing system checks...

System check identified no issues (0 silenced).
Exception in thread django-main-thread:
Traceback (most recent call last):
  File "/usr/local/Cellar/python@3.11/3.11.13/Frameworks/Python.framework/Versions/3.11/lib/python3.11/threading.py", line 1045, in _bootstrap_inner
    self.run()
  File "/usr/local/Cellar/python@3.11/3.11.13/Frameworks/Python.framework/Versions/3.11/lib/python3.11/threading.py", line 982, in run
    self._target(*self._args, **self._kwargs)
  File "/Users/syedsmacbook/Developer/mawaddah-admin-panel/venv/lib/python3.11/site-packages/django/utils/autoreload.py", line 64, in wrapper
    fn(*args, **kwargs)
  File "/Users/syedsmacbook/Developer/mawaddah-admin-panel/venv/lib/python3.11/site-packages/django/core/management/commands/runserver.py", line 136, in inner_run
    self.check_migrations()
  File "/Users/syedsmacbook/Developer/mawaddah-admin-panel/venv/lib/python3.11/site-packages/django/core/management/base.py", line 574, in check_migrations
    executor = MigrationExecutor(connections[DEFAULT_DB_ALIAS])
               ^^^^^^^^^^^^^^^^^^^^^^^^^^^^^^^^^^^^^^^^^^^^^^^^
  File "/Users/syedsmacbook/Developer/mawaddah-admin-panel/venv/lib/python3.11/site-packages/django/db/migrations/executor.py", line 18, in __init__
    self.loader = MigrationLoader(self.connection)
                  ^^^^^^^^^^^^^^^^^^^^^^^^^^^^^^^^
  File "/Users/syedsmacbook/Developer/mawaddah-admin-panel/venv/lib/python3.11/site-packages/django/db/migrations/loader.py", line 58, in __init__
    self.build_graph()
  File "/Users/syedsmacbook/Developer/mawaddah-admin-panel/venv/lib/python3.11/site-packages/django/db/migrations/loader.py", line 235, in build_graph
    self.applied_migrations = recorder.applied_migrations()
                              ^^^^^^^^^^^^^^^^^^^^^^^^^^^^^
  File "/Users/syedsmacbook/Developer/mawaddah-admin-panel/venv/lib/python3.11/site-packages/django/db/migrations/recorder.py", line 81, in applied_migrations
    if self.has_table():
       ^^^^^^^^^^^^^^^^
  File "/Users/syedsmacbook/Developer/mawaddah-admin-panel/venv/lib/python3.11/site-packages/django/db/migrations/recorder.py", line 57, in has_table
    with self.connection.cursor() as cursor:
         ^^^^^^^^^^^^^^^^^^^^^^^^
  File "/Users/syedsmacbook/Developer/mawaddah-admin-panel/venv/lib/python3.11/site-packages/django/utils/asyncio.py", line 26, in inner
    return func(*args, **kwargs)
           ^^^^^^^^^^^^^^^^^^^^^
  File "/Users/syedsmacbook/Developer/mawaddah-admin-panel/venv/lib/python3.11/site-packages/django/db/backends/base/base.py", line 330, in cursor
    return self._cursor()
           ^^^^^^^^^^^^^^
  File "/Users/syedsmacbook/Developer/mawaddah-admin-panel/venv/lib/python3.11/site-packages/django/db/backends/base/base.py", line 306, in _cursor
    self.ensure_connection()
  File "/Users/syedsmacbook/Developer/mawaddah-admin-panel/venv/lib/python3.11/site-packages/django/utils/asyncio.py", line 26, in inner
    return func(*args, **kwargs)
           ^^^^^^^^^^^^^^^^^^^^^
  File "/Users/syedsmacbook/Developer/mawaddah-admin-panel/venv/lib/python3.11/site-packages/django/db/backends/base/base.py", line 289, in ensure_connection
    self.connect()
  File "/Users/syedsmacbook/Developer/mawaddah-admin-panel/venv/lib/python3.11/site-packages/django/utils/asyncio.py", line 26, in inner
    return func(*args, **kwargs)
           ^^^^^^^^^^^^^^^^^^^^^
  File "/Users/syedsmacbook/Developer/mawaddah-admin-panel/venv/lib/python3.11/site-packages/django/db/backends/base/base.py", line 270, in connect
    self.connection = self.get_new_connection(conn_params)
                      ^^^^^^^^^^^^^^^^^^^^^^^^^^^^^^^^^^^^
  File "/Users/syedsmacbook/Developer/mawaddah-admin-panel/venv/lib/python3.11/site-packages/django/utils/asyncio.py", line 26, in inner
    return func(*args, **kwargs)
           ^^^^^^^^^^^^^^^^^^^^^
  File "/Users/syedsmacbook/Developer/mawaddah-admin-panel/venv/lib/python3.11/site-packages/django/db/backends/sqlite3/base.py", line 180, in get_new_connection
    conn = Database.connect(**conn_params)
           ^^^^^^^^^^^^^^^^^^^^^^^^^^^^^^^
TypeError: 'sslmode' is an invalid keyword argument for Connection()
